Workbook

Sheet README
A1: Workbook | B1: Azure Cost Model - ArticlePod
A2: Generated | B2: 2026-02-15T00:29:43.234Z
A3: Region | B3: eastus
A4: Currency | B4: USD
A5: How to use | B5: Go to Inputs tab, change green cells, pick scenario in B3, and review Finance_Summary.
A6: Legend Input | B6: Green cells are editable assumptions
A7: Legend Calculated | B7: Blue cells are formulas or computed outputs
A8: Pricing source | B8: https://prices.azure.com/api/retail/prices

Sheet Inputs
A1: Section | B1: Parameter | C1: Value | D1: Unit | E1: Low | F1: High
A2: Scenario | B2: Selected Scenario | C2: Base | D2: (Low/Base/High)
A3: Global | B3: Days per month | C3: 30.4 | D3: days
A4: Global | B4: Hours per month | C4: 730 | D4: hours
A5: Global | B5: Headroom factor | C5: 1.3 | D5: x
A6: Global | B6: VM count | C6: 1 | D6: count
A7: Global | B7: TTS success rate | C7: 0.97 | D7: fraction
A8: Global | B8: Retry rate | C8: 0.08 | D8: fraction
A9: Global | B9: DB backup multiplier | C9: 1.2 | D9: x
A11: Infra sizing knobs | B11: Knob | C11: Value | D11: Unit
A12: Infra sizing knobs | B12: Postgres vCores | C12: 2 | D12: count
A13: Infra sizing knobs | B13: Postgres storage GB | C13: 128 | D13: GB
A14: Infra sizing knobs | B14: Blob storage floor GB | C14: 128 | D14: GB
A15: Infra sizing knobs | B15: Blob audio retention multiplier | C15: 3 | D15: x
A16: Infra sizing knobs | B16: Table storage minimum GB | C16: 5 | D16: GB
A17: Infra sizing knobs | B17: Table DB growth multiplier | C17: 2 | D17: x
A19: Cohort | B19: Knob | C19: Free | D19: Pro | E19: Team | F19: Unit
A20: Users | B20: Active users | C20: 2000 | D20: 500 | E20: 80 | F20: count
A21: Usage | B21: Articles per user per day | C21: 0.4 | D21: 1.2 | E21: 4 | F21: count/day
A22: Usage | B22: Peak submissions per hour /1000 users | C22: 35 | D22: 55 | E22: 95 | F22: count/hour
A23: Content | B23: Average article minutes | C23: 6 | D23: 10 | E23: 14 | F23: minutes
A24: Content | B24: Average words per article | C24: 900 | D24: 1700 | E24: 2500 | F24: words
A25: Mix | B25: % URL | C25: 0.7 | D25: 0.7 | E25: 0.6 | F25: fraction
A26: Mix | B26: % PDF | C26: 0.2 | D26: 0.2 | E26: 0.25 | F26: fraction
A27: Mix | B27: % HTML snapshot | C27: 0.1 | D27: 0.1 | E27: 0.15 | F27: fraction
A28: Media | B28: Output audio MB per minute | C28: 0.45 | D28: 0.45 | E28: 0.45 | F28: MB/min
A29: Media | B29: Blob reads per episode per month | C29: 2.2 | D29: 2.8 | E29: 4.5 | F29: count
A30: Network | B30: Egress GB per user per month | C30: 0.18 | D30: 0.55 | E30: 1.8 | F30: GB/month
A31: DB | B31: DB rows per article | C31: 14 | D31: 18 | E31: 26 | F31: rows
... A33: Table | B33: Table ops per article | C33: 18 | D33: 28 | E33: 42 | F33: ops
A35: Scenario Multipliers | B35: Scenario | C35: User multiplier | D35: Usage multiplier | E35: Egress multiplier
A36: Scenario Multipliers | B36: Low | C36: 0.7 | D36: 0.75 | E36: 0.8
A37: Scenario Multipliers | B37: Base | C37: 1 | D37: 1 | E37: 1
A38: Scenario Multipliers | B38: High | C38: 1.6 | D38: 1.4 | E38: 1.5
A40: Prices | B40: Meter | C40: Value | D40: Unit
A41: Prices | B41: VM hourly PAYG | C41: 0.172 | D41: USD/hour
A42: Prices | B42: VM reservation 1Y | C42: 889 | D42: USD upfront
A43: Prices | B43: VM reservation 3Y | C43: 1718 | D43: USD upfront
A44: Prices | B44: Postgres vCore hourly PAYG | C44: 0.089 | D44: USD/hour
A45: Prices | B45: Postgres vCore reservation 1Y | C45: 468 | D45: USD upfront
...

Sheet Formulas
A1: Metric | B1: Formula (per cohort) | C1: Free | D1: Pro | E1: Team | F1: Total
A2: Submissions / month | B2: users * articles/day * days/month * multipliers | C2: =Inputs!C12*IF(Inputs!C2="Low",Inputs!C36,IF(Inputs!C2="High",Inputs!C38,Inputs!C37))*Inputs!C13*IF(Inputs!C2="Low",Inputs!D36,IF(Inputs!C2="High",Inputs!D38,Inputs!D37))*Inputs!C3 | D2: =Inputs!D12*IF(Inputs!C2="Low",Inputs!C36,IF(Inputs!C2="High",Inputs!C38,Inputs!C37))*Inputs!D13*IF(Inputs!C2="Low",Inputs!D36,IF(Inputs!C2="High",Inputs!D38,Inputs!D37))*Inputs!C3 | E2: =Inputs!E12*IF(Inputs!C2="Low",Inputs!C36,IF(Inputs!C2="High",Inputs!C38,Inputs!C37))*Inputs!E13*IF(Inputs!C2="Low",Inputs!D36,IF(Inputs!C2="High",Inputs!D38,Inputs!D37))*Inputs!C3 | F2: =SUM(C2:E2)
A3: Effective jobs / month | B3: submissions * (1+retry) | C3: =C2*(1+Inputs!C8) | D3: =D2*(1+Inputs!C8) | E3: =E2*(1+Inputs!C8) | F3: =SUM(C3:E3)
A4: Ready episodes / month | B4: effective jobs * success rate | C4: =C3*Inputs!C7 | D4: =D3*Inputs!C7 | E4: =E3*Inputs!C7 | F4: =SUM(C4:E4)
A5: Audio minutes / month | B5: ready episodes * avg article minutes | C5: =C4*Inputs!C15*IF(Inputs!C2="Low",Inputs!D36,IF(Inputs!C2="High",Inputs!D38,Inputs!D37)) | D5: =D4*Inputs!D15*IF(Inputs!C2="Low",Inputs!D36,IF(Inputs!C2="High",Inputs!D38,Inputs!D37)) | E5: =E4*Inputs!E15*IF(Inputs!C2="Low",Inputs!D36,IF(Inputs!C2="High",Inputs!D38,Inputs!D37)) | F5: =SUM(C5:E5)
A6: Audio GB / month | B6: audio minutes * mb/min / 1024 | C6: =(C5*Inputs!C20)/1024 | D6: =(D5*Inputs!D20)/1024 | E6: =(E5*Inputs!E20)/1024 | F6: =SUM(C6:E6)
A7: Blob reads / month | B7: ready episodes * reads/episode | C7: =C4*Inputs!C21 | D7: =D4*Inputs!D21 | E7: =E4*Inputs!E21 | F7: =SUM(C7:E7)
A8: Egress GB / month | B8: users * egress/user * multiplier | C8: =Inputs!C12*IF(Inputs!C2="Low",Inputs!C36,IF(Inputs!C2="High",Inputs!C38,Inputs!C37))*Inputs!C22*IF(Inputs!C2="Low",Inputs!E36,IF(Inputs!C2="High",Inputs!E38,Inputs!E37)) | D8: =Inputs!D12*IF(Inputs!C2="Low",Inputs!C36,IF(Inputs!C2="High",Inputs!C38,Inputs!C37))*Inputs!D22*IF(Inputs!C2="Low",Inputs!E36,IF(Inputs!C2="High",Inputs!E38,Inputs!E37)) | E8: =Inputs!E12*IF(Inputs!C2="Low",Inputs!C36,IF(Inputs!C2="High",Inputs!C38,Inputs!C37))*Inputs!E22*IF(Inputs!C2="Low",Inputs!E36,IF(Inputs!C2="High",Inputs!E38,Inputs!E37)) | F8: =SUM(C8:E8)
A9: DB growth GB / month | B9: effective jobs * KB/article / (1024*1024) | C9: =(C3*Inputs!C24)/(1024*1024) | D9: =(D3*Inputs!D24)/(1024*1024) | E9: =(E3*Inputs!E24)/(1024*1024) | F9: =SUM(C9:E9)
A10: Table ops / month | B10: effective jobs * ops/article | C10: =C3*Inputs!C25 | D10: =D3*Inputs!D25 | E10: =E3*Inputs!E25 | F10: =SUM(C10:E10)
A11: Peak submissions / hour | B11: (users/1000) * peak_submissions_per_1000 * scenario usage multiplier | C11: =(Inputs!C12/1000)*Inputs!C14*IF(Inputs!C2="Low",Inputs!D36,IF(Inputs!C2="High",Inputs!D38,Inputs!D37)) | D11: =(Inputs!D12/1000)*Inputs!D14*IF(Inputs!C2="Low",Inputs!D36,IF(Inputs!C2="High",Inputs!D38,Inputs!D37)) | E11: =(Inputs!E12/1000)*Inputs!E14*IF(Inputs!C2="Low",Inputs!D36,IF(Inputs!C2="High",Inputs!D38,Inputs!D37)) | F11: =SUM(C11:E11)
A12: TTS capacity minutes / VM / month | B12: hours * 60 * realtime_factor * utilization * (1-overhead) | F12: =Inputs!C4*60*Inputs!C59*Inputs!C60*(1-Inputs!C61)
A13: Required VMs (TTS) | B13: ceil(audio_minutes / tts_capacity_per_vm) | F13: =MAX(1,ROUNDUP(F5/F12,0))
A14: Required VMs (API peak) | B14: ceil((peak_submissions_hour * headroom)/api_capacity_per_vm_hour) | F14: =MAX(1,ROUNDUP((F11*Inputs!C5)/Inputs!C62,0))
A15: Required VMs (total) | B15: max(base_vm_count, vm_tts, vm_api) | F15: =MAX(Inputs!C6,F13,F14)

Sheet Prices
A1: Category | B1: Meter | C1: Price | D1: Unit | E1: Snapshot generated
A2: VM | B2: VM hourly PAYG | C2: 0.172 | D2: USD/hour | E2: 2026-02-15T00:29:43.234Z
A3: VM | B3: VM RI 1Y | C3: 889 | D3: USD upfront | E3: 2026-02-15T00:29:43.234Z
A4: VM | B4: VM RI 3Y | C4: 1718 | D4: USD upfront | E4: 2026-02-15T00:29:43.234Z
A5: Postgres | B5: vCore hourly PAYG | C5: 0.089 | D5: USD/hour | E5: 2026-02-15T00:29:43.234Z
A6: Postgres | B6: vCore RI 1Y | C6: 468 | D6: USD upfront | E6: 2026-02-15T00:29:43.234Z
A7: Postgres | B7: vCore RI 3Y | C7: 936 | D7: USD upfront | E7: 2026-02-15T00:29:43.234Z
A8: Postgres | B8: Storage | C8: 0.115 | D8: USD/GB-month | E8: 2026-02-15T00:29:43.234Z
A9: Postgres | B9: Backup | C9: 0.095 | D9: USD/GB-month | E9: 2026-02-15T00:29:43.234Z
A10: Blob | B10: Hot LRS storage | C10: 0.0208 | D10: USD/GB-month | E10: 2026-02-15T00:29:43.234Z
A11: Blob | B11: Write ops | C11: 0.05 | D11: USD/10k | E11: 2026-02-15T00:29:43.234Z
A12: Blob | B12: Read ops | C12: 0.004 | D12: USD/10k | E12: 2026-02-15T00:29:43.234Z
A13: Table | B13: LRS storage | C13: 0.045 | D13: USD/GB-month | E13: 2026-02-15T00:29:43.234Z
... A17: VM | B17: OS disk | C17: 5.2795 | D17: USD/month | E17: 2026-02-15T00:29:43.234Z

Sheet Cost_Breakdown
A1: Component | B1: Formula | C1: Monthly USD | D1: Annual USD | E1: % of monthly
A2: VM compute | B2: vm_hourly * hours * required_vm_count | C2: =Inputs!C41*Inputs!C4*Formulas!F15 | D2: =Inputs!C41*Inputs!C4*Formulas!F15*12 | E2: =C2/SUM(C2:C13)
A3: VM public IP | B3: public_ip_hourly * hours | C3: =Inputs!C55*Inputs!C4 | D3: =Inputs!C55*Inputs!C4*12 | E3: =C3/SUM(C2:C13)
A4: VM OS disk | B4: os_disk_month | C4: =Inputs!C56 | D4: =Inputs!C56*12 | E4: =C4/SUM(C2:C13)
A5: Postgres compute | B5: pg_vcore_3yr_reserved * vcores / 36 | C5: =(Inputs!C46/36)*Inputs!C12 | D5: =(Inputs!C46/36)*Inputs!C12*12 | E5: =C5/SUM(C2:C13)
A6: Postgres storage | B6: pg_storage_rate * configured_pg_gb | C6: =Inputs!C47*Inputs!C13 | D6: =Inputs!C47*Inputs!C13*12 | E6: =C6/SUM(C2:C13)
A7: Postgres backup | B7: pg_backup_rate * configured_pg_gb * backup_multiplier | C7: =Inputs!C48*Inputs!C13*Inputs!C9 | D7: =Inputs!C48*Inputs!C13*Inputs!C9*12 | E7: =C7/SUM(C2:C13)
A8: Blob storage | B8: blob_rate * MAX(blob_floor_gb, audio_gb*retention_mult) | C8: =Inputs!C49*MAX(Inputs!C14,Formulas!F6*Inputs!C15) | D8: =Inputs!C49*MAX(Inputs!C14,Formulas!F6*Inputs!C15)*12 | E8: =C8/SUM(C2:C13)
A9: Blob write ops | B9: write_rate * episodes/10k | C9: =Inputs!C50*(Formulas!F4/10000) | D9: =Inputs!C50*(Formulas!F4/10000)*12 | E9: =C9/SUM(C2:C13)
A10: Blob read ops | B10: read_rate * blob_reads/10k | C10: =Inputs!C51*(Formulas!F7/10000) | D10: =Inputs!C51*(Formulas!F7/10000)*12 | E10: =C10/SUM(C2:C13)
A11: Table storage | B11: table_rate * MAX(table_min_gb, db_growth*table_mult) | C11: =Inputs!C52*MAX(Inputs!C16,Formulas!F9*Inputs!C17) | D11: =Inputs!C52*MAX(Inputs!C16,Formulas!F9*Inputs!C17)*12 | E11: =C11/SUM(C2:C13)
A12: Table ops | B12: table_ops_rate * table_ops/10k | C12: =Inputs!C53*(Formulas!F10/10000) | D12: =Inputs!C53*(Formulas!F10/10000)*12 | E12: =C12/SUM(C2:C13)
A13: Network egress | B13: egress_rate * egress_gb | C13: =Inputs!C54*Formulas!F8 | D13: =Inputs!C54*Formulas!F8*12 | E13: =C13/SUM(C2:C13)
A14: Total | B14: sum | C14: =SUM(C2:C13) | D14: =SUM(D2:D13) | E14: 100%

Sheet Commitment_Compare
A1: Strategy | B1: Monthly USD | C1: Annual USD | D1: Savings vs PAYG (USD/mo) | E1: Savings %
A2: PAYG baseline | B2: =Cost_Breakdown!C14 | C2: =Cost_Breakdown!C14*12 | D2: =B2-(Cost_Breakdown!C14) | E2: =IF(B2=0,0,(B2-(Cost_Breakdown!C14))/B2)
A3: VM only - 1Y RI | B3: =Cost_Breakdown!C14 - Cost_Breakdown!C2 + (Inputs!C42/12)*Formulas!F15 | C3: =Cost_Breakdown!C14 - Cost_Breakdown!C2 + (Inputs!C42/12)*Formulas!F15*12 | D3: =B2-(Cost_Breakdown!C14 - Cost_Breakdown!C2 + (Inputs!C42/12)*Formulas!F15) | E3: =IF(B2=0,0,(B2-(Cost_Breakdown!C14 - Cost_Breakdown!C2 + (Inputs!C42/12)*Formulas!F15))/B2)
A4: VM only - 3Y RI | B4: =Cost_Breakdown!C14 - Cost_Breakdown!C2 + (Inputs!C43/36)*Formulas!F15 | C4: =Cost_Breakdown!C14 - Cost_Breakdown!C2 + (Inputs!C43/36)*Formulas!F15*12 | D4: =B2-(Cost_Breakdown!C14 - Cost_Breakdown!C2 + (Inputs!C43/36)*Formulas!F15) | E4: =IF(B2=0,0,(B2-(Cost_Breakdown!C14 - Cost_Breakdown!C2 + (Inputs!C43/36)*Formulas!F15))/B2)
A5: Postgres only - 1Y RI | B5: =Cost_Breakdown!C14 - Cost_Breakdown!C5 + (Inputs!C45/12)*Inputs!C12 | C5: =Cost_Breakdown!C14 - Cost_Breakdown!C5 + (Inputs!C45/12)*Inputs!C12*12 | D5: =B2-(Cost_Breakdown!C14 - Cost_Breakdown!C5 + (Inputs!C45/12)*Inputs!C12) | E5: =IF(B2=0,0,(B2-(Cost_Breakdown!C14 - Cost_Breakdown!C5 + (Inputs!C45/12)*Inputs!C12))/B2)
A6: Postgres only - 3Y RI | B6: =Cost_Breakdown!C14 - Cost_Breakdown!C5 + (Inputs!C46/36)*Inputs!C12 | C6: =Cost_Breakdown!C14 - Cost_Breakdown!C5 + (Inputs!C46/36)*Inputs!C12*12 | D6: =B2-(Cost_Breakdown!C14 - Cost_Breakdown!C5 + (Inputs!C46/36)*Inputs!C12) | E6: =IF(B2=0,0,(B2-(Cost_Breakdown!C14 - Cost_Breakdown!C5 + (Inputs!C46/36)*Inputs!C12))/B2)
A7: VM + Postgres - 1Y RI | B7: =Cost_Breakdown!C14 - Cost_Breakdown!C2 - Cost_Breakdown!C5 + (Inputs!C42/12)*Formulas!F15 + (Inputs!C45/12)*Inputs!C12 | C7: =Cost_Breakdown!C14 - Cost_Breakdown!C2 - Cost_Breakdown!C5 + (Inputs!C42/12)*Formulas!F15 + (Inputs!C45/12)*Inputs!C12*12 | D7: =B2-(Cost_Breakdown!C14 - Cost_Breakdown!C2 - Cost_Breakdown!C5 + (Inputs!C42/12)*Formulas!F15 + (Inputs!C45/12)*Inputs!C12) | E7: =IF(B2=0,0,(B2-(Cost_Breakdown!C14 - Cost_Breakdown!C2 - Cost_Breakdown!C5 + (Inputs!C42/12)*Formulas!F15 + (Inputs!C45/12)*Inputs!C12))/B2)
A8: VM + Postgres - 3Y RI | B8: =Cost_Breakdown!C14 - Cost_Breakdown!C2 - Cost_Breakdown!C5 + (Inputs!C43/36)*Formulas!F15 + (Inputs!C46/36)*Inputs!C12 | C8: =Cost_Breakdown!C14 - Cost_Breakdown!C2 - Cost_Breakdown!C5 + (Inputs!C43/36)*Formulas!F15 + (Inputs!C46/36)*Inputs!C12*12 | D8: =B2-(Cost_Breakdown!C14 - Cost_Breakdown!C2 - Cost_Breakdown!C5 + (Inputs!C43/36)*Formulas!F15 + (Inputs!C46/36)*Inputs!C12) | E8: =IF(B2=0,0,(B2-(Cost_Breakdown!C14 - Cost_Breakdown!C2 - Cost_Breakdown!C5 + (Inputs!C43/36)*Formulas!F15 + (Inputs!C46/36)*Inputs!C12))/B2)

Sheet Pricing_Strategy
A1: Metric | B1: Value | C1: Formula / notes
A2: Modeled monthly cost (selected scenario) | B2: =Cost_Breakdown!C14 | C2: from Cost_Breakdown
A3: Required monthly revenue for 90% margin | B3: =B2/(1-Inputs!C65) | C3: revenue = cost/(1-margin)
A4: Required monthly revenue for 95% margin | B4: =B2/(1-Inputs!C66) | C4: revenue = cost/(1-margin)
A6: Scenario-adjusted Pro users | B6: =Inputs!D12*IF(Inputs!C2="Low",Inputs!C36,IF(Inputs!C2="High",Inputs!C38,Inputs!C37)) | C6: Pro active users in selected scenario
A7: Scenario-adjusted Team users | B7: =Inputs!E12*IF(Inputs!C2="Low",Inputs!C36,IF(Inputs!C2="High",Inputs!C38,Inputs!C37)) | C7: Team active users in selected scenario
A8: Total active users (all cohorts) | B8: =((Inputs!C12+Inputs!D12+Inputs!E12)*IF(Inputs!C2="Low",Inputs!C36,IF(Inputs!C2="High",Inputs!C38,Inputs!C37))) | C8: used by conversion mode
A9: Conversion-mode Pro users | B9: =B8*Inputs!C69 | C9: from conversion rate
A10: Conversion-mode Team users | B10: =B8*Inputs!C70 | C10: from conversion rate
A11: Tier-count mode paying users (Pro+Team) | B11: =B6+B7 | C11: free tier excluded
A12: Active pricing mode | B12: =Inputs!C68 | C12: tier_counts or conversion_based
A13: Selected Pro users | B13: =IF(B12="conversion_based",B9,B6) | C13: users used for pricing solve
A14: Selected Team users | B14: =IF(B12="conversion_based",B10,B7) | C14: users used for pricing solve
A15: Total paying users (selected mode) | B15: =B13+B14 | C15: for blended ARPU
A16: Team price multiplier vs Pro | B16: =Inputs!C67 | C16: editable in Inputs
A17: Price denominator (Pro + Team*multiplier) | B17: =B13 + (B14*B16) | C17: for solving two-tier pricing
A19: Recommended Pro price @90% margin | B19: =IF(B17=0,0,B3/B17) | C19: monthly price per Pro user
A20: Recommended Team price @90% margin | B20: =B19*B16 | C20: monthly price per Team user
A21: Blended ARPU needed @90% margin | B21: =IF(B15=0,0,B3/B15) | C21: monthly revenue / paying user
A23: Recommended Pro price @95% margin | B23: =IF(B17=0,0,B4/B17) | C23: monthly price per Pro user
A24: Recommended Team price @95% margin | B24: =B23*B16 | C24: monthly price per Team user
A25: Blended ARPU needed @95% margin | B25: =IF(B15=0,0,B4/B15) | C25: monthly revenue / paying user
A27: Margin check @95 pricing | B27: =IF((B23*B13+B24*B14)=0,0,1-(B2/(B23*B13+B24*B14))) | C27: should approximate target margin

Sheet Sensitivity
A1: Case | B1: Load multiplier | C1: Monthly USD | D1: Delta vs base
A2: Base | B2: 1 | C2: =Cost_Breakdown!C14 | D2: 0
A3: Low (-25%) | B3: 0.75 | C3: =Cost_Breakdown!C14*0.75 | D3: =C3-C2
A4: High (+25%) | B4: 1.25 | C4: =Cost_Breakdown!C14*1.25 | D4: =C4-C2
A5: Stress (+50%) | B5: 1.5 | C5: =Cost_Breakdown!C14*1.5 | D5: =C5-C2

Sheet Finance_Summary
A1: Metric | B1: Value | C1: Notes
A2: Selected scenario | B2: =Inputs!C2 | C2: Low/Base/High toggle on Inputs tab
A3: Monthly total cost | B3: =Cost_Breakdown!C14 | C3: USD/month
A4: Annual total cost | B4: =Cost_Breakdown!D14 | C4: USD/year
A5: Estimated required VM count | B5: =Formulas!F15 | C5: Computed from TTS + API peak
A6: Required VMs for TTS only | B6: =Formulas!F13 | C6: Capacity from Kokoro realtime factor
A7: Required VMs for API peak only | B7: =Formulas!F14 | C7: Headroom-adjusted request peak
A8: Best commitment monthly | B8: =MIN(Commitment_Compare!B2:B8) | C8: Lowest modeled monthly cost
A9: Required revenue @90% margin | B9: =Pricing_Strategy!B3 | C9: monthly
A10: Required revenue @95% margin | B10: =Pricing_Strategy!B4 | C10: monthly
A11: Recommended Pro price @95% | B11: =Pricing_Strategy!B23 | C11: monthly
A12: Recommended Team price @95% | B12: =Pricing_Strategy!B24 | C12: monthly
A13: Best commitment strategy | B13: VM + Postgres - 3Y RI | C13: From Commitment_Compare table
A14: Top cost driver | B14: VM + Postgres compute | C14: Review Cost_Breakdown % column
A15: Architecture baseline | B15: Standard_D4as_v5, General Purpose Ddsv4 (2 vCore equivalent), Blob Hot LRS | C15: from infra/main.bicep
A16: Pricing snapshot timestamp | B16: 2026-02-15T00:29:43.234Z | C16: Azure Retail Prices API
